Workbook

Sheet EDT
A2: Matriz Estructura de descomposición de tareas EDT
A4: Etapas | B4: DIAS | C4: HORAS POR ACTIVIDAD O ENTREGABLE | I4: DICCIONARIO EDT
A5: Fase de Planificación | C5: Jefe de Proyecto | D5: Analista Programador | E5: DBA | F5: QA | G5: Diseñador | I5: ROL ACTOR | J5: NOMBRE ACTOR
A6: Acta de Constitución de proyecto | B6: 3 | C6: 5 | D6: 2 | E6: 2 | F6: 2 | G6: 2 | I6: Jefe de Proyecto | J6: Christian Soto
A7: Aprobación del Acta | B7: 1 | C7: 2 | D7: 1 | E7: 1 | F7: 1 | G7: 1 | I7: Analista Programador | J7: Kevin Herrera
A8: Definición de requerimientos Generales | B8: 5 | C8: 5 | D8: 5 | E8: 2 | F8: 2 | G8: 2 | I8: DBA | J8: Gerald Silva
A9: Organización del equipo | B9: 2 | C9: 3 | D9: 1 | E9: 1 | F9: 1 | G9: 1 | I9: QA | J9: Kevin Herrera
A10: TOTAL FASE DE PLANIFICACIÓN | B10: =SUM(B6:B9) -> 11 | C10: =SUM(C6:C9) -> 15 | D10: =SUM(D6:D9) -> 9 | E10: =SUM(E6:E9) -> 6 | F10: =SUM(F6:F9) -> 6 | G10: =SUM(G6:G9) -> 6 | I10: Diseñador | J10: Gerald Silva
A12: Fase de Análisis y diseño | C12: Jefe de Proyecto | D12: Analista Programador | E12: DBA | F12: QA | G12: Diseñador
A13: Captura de requerimientos específicos | B13: 6 | C13: 4 | D13: 8 | E13: 3 | F13: 3 | G13: 2
A14: Documento de arquitectura SW | B14: 4 | C14: 2 | D14: 7 | E14: 5 | F14: 2 | G14: 2
A15: Modelo de datos y diagrama de BBDD | B15: 4 | C15: 2 | D15: 2 | E15: 9 | F15: 2 | G15: 0
A16: Documento de casos de uso | B16: 4 | C16: 2 | D16: 7 | E16: 2 | F16: 3 | G16: 2
A17: Prototipos (mockups de las pantallas) | B17: 5 | C17: 2 | D17: 2 | E17: 0 | F17: 2 | G17: 10
A18: Propuesta ERS | B18: 4 | C18: 3 | D18: 5 | E18: 2 | F18: 2 | G18: 2
A19: TOTAL FASE DE ANÁLISIS Y DISEÑO | B19: =SUM(B13:B18) -> 27 | C19: =SUM(C13:C18) -> 15 | D19: =SUM(D13:D18) -> 31 | E19: =SUM(E13:E18) -> 21 | F19: =SUM(F13:F18) -> 14 | G19: =SUM(G13:G18) -> 18
A21: Fase de Desarrollo | C21: Jefe de Proyecto | D21: Analista Programador | E21: DBA | F21: QA | G21: Diseñador
A22: Implementación ambiente de desarrollo | B22: 3 | C22: 2 | D22: 5 | E22: 2 | F22: 2 | G22: 2
A23: Creación de los script de tablas base de datos | B23: 6 | C23: 2 | D23: 3 | E23: 16 | F23: 1 | G23: 0
A24: Creación de los script de consultas PL/pgSQL (RLS, funciones y vistas) | B24: 8 | C24: 2 | D24: 4 | E24: 21 | F24: 3 | G24: 0
A25: Módulo de Autenticación y Acceso
A26: Pantalla de ingreso por empresa con branding | B26: 3 | C26: 1 | D26: 6 | E26: 2 | F26: 1 | G26: 3
A27: Edge Functions de login (solicitar / verificar) | B27: 4 | C27: 1 | D27: 9 | E27: 2 | F27: 1 | G27: 0
A28: Hook de claims JWT y helpers de contexto | B28: 3 | C28: 1 | D28: 2 | E28: 6 | F28: 1 | G28: 0
A29: Canje de enlace mágico y código de un solo uso | B29: 3 | C29: 1 | D29: 6 | E29: 2 | F29: 1 | G29: 2
A30: Módulo de Administración de Usuarios
A31: Alta en cascada de jefes y colaboradores | B31: 4 | C31: 1 | D31: 8 | E31: 2 | F31: 1 | G31: 1
A32: Mantenedor de áreas jerárquicas | B32: 3 | C32: 1 | D32: 4 | E32: 5 | F32: 1 | G32: 2
A33: Módulo de Gestión de Encuestas
A34: Lanzamiento de encuesta y cuenta regresiva | B34: 4 | C34: 2 | D34: 8 | E34: 4 | F34: 1 | G34: 1
A35: Envío de invitaciones por correo | B35: 3 | C35: 1 | D35: 6 | E35: 1 | F35: 1 | G35: 0
A36: Recordatorios automáticos y recordatorio manual | B36: 3 | C36: 1 | D36: 5 | E36: 3 | F36: 1 | G36: 0
A37: Módulo de Respuesta a la Encuesta
A38: Cuestionario por dimensión y subdimensión | B38: 5 | C38: 1 | D38: 9 | E38: 2 | F38: 2 | G38: 3
A39: Selección de emociones del colaborador | B39: 2 | C39: 1 | D39: 3 | E39: 1 | F39: 2 | G39: 2
A40: Envío y sellado de la participación | B40: 3 | C40: 1 | D40: 4 | E40: 4 | F40: 1 | G40: 0
A41: Módulo de Informes y Reportes
A42: Funciones de reporte con umbral de anonimato | B42: 5 | C42: 2 | D42: 4 | E42: 12 | F42: 2 | G42: 0
A43: Panel de gerencia (resumen de la medición) | B43: 5 | C43: 2 | D43: 10 | E43: 1 | F43: 2 | G43: 4
A44: Informes por dimensión, área e histórico | B44: 4 | C44: 1 | D44: 8 | E44: 2 | F44: 1 | G44: 2
...

Sheet Costos Fases
A2: SIGLA | B2: ROL | C2: NOMBRE | D2: VALOR HORA HH | E2: HORAS | F2: FASE PLANIFICACION | H2: COSTO POR HORA
A3: JP | B3: Jefe de Proyecto | C3: =IF(EDT!$J$6="","",EDT!$J$6) -> Christian Soto | D3: =$J$4 -> 16000 | E3: =EDT!C10 -> 15 | F3: =D3*E3 -> 240000 | H3: ROL | I3: NOMBRE | J3: COSTO x HORA | K3: Sueldo mes
A4: AP | B4: Analista Programador | C4: =IF(EDT!$J$7="","",EDT!$J$7) -> Kevin Herrera | D4: =$J$5 -> 12000 | E4: =EDT!D10 -> 9 | F4: =D4*E4 -> 108000 | H4: Jefe de Proyecto | I4: =IF(EDT!$J$6="","",EDT!$J$6) -> Christian Soto | J4: 16000
A5: DBA | B5: Desarrollador BD | C5: =IF(EDT!$J$8="","",EDT!$J$8) -> Gerald Silva | D5: =$J$6 -> 12000 | E5: =EDT!E10 -> 6 | F5: =D5*E5 -> 72000 | H5: Analista Programador | I5: =IF(EDT!$J$7="","",EDT!$J$7) -> Kevin Herrera | J5: 12000
A6: QA | B6: Calidad Y Testing | C6: =IF(EDT!$J$9="","",EDT!$J$9) -> Kevin Herrera | D6: =$J$7 -> 8500 | E6: =EDT!F10 -> 6 | F6: =D6*E6 -> 51000 | H6: Administrador BD | I6: =IF(EDT!$J$8="","",EDT!$J$8) -> Gerald Silva | J6: 12000
A7: DI | B7: Diseñador | C7: =IF(EDT!$J$10="","",EDT!$J$10) -> Gerald Silva | D7: =$J$8 -> 8500 | E7: =EDT!G10 -> 6 | F7: =D7*E7 -> 51000 | H7: Calidad Y Testing | I7: =IF(EDT!$J$9="","",EDT!$J$9) -> Kevin Herrera | J7: 8500
B8: TOTAL FASE PLANIFICACION | E8: =SUM(E3:E7) -> 42 | F8: =SUM(F3:F7) -> 522000 | H8: Diseñador | I8: =IF(EDT!$J$10="","",EDT!$J$10) -> Gerald Silva | J8: 8500
A11: SIGLA | B11: ROL | C11: NOMBRE | D11: VALOR HORA HH | E11: HORAS | F11: FASE DISEÑO | H11: COSTO HH POR ROL
A12: JP | B12: Jefe de Proyecto | C12: =IF(EDT!$J$6="","",EDT!$J$6) -> Christian Soto | D12: =$J$4 -> 16000 | E12: =EDT!C19 -> 15 | F12: =D12*E12 -> 240000 | H12: Jefe de Proyecto | I12: =F3+F12+F21+F30+F39 -> 1216000
A13: AP | B13: Analista Programador | C13: =IF(EDT!$J$7="","",EDT!$J$7) -> Kevin Herrera | D13: =$J$5 -> 12000 | E13: =EDT!D19 -> 31 | F13: =D13*E13 -> 372000 | H13: Analista Programador | I13: =F4+F13+F22+F31+F40 -> 2424000
A14: DBA | B14: Desarrollador BD | C14: =IF(EDT!$J$8="","",EDT!$J$8) -> Gerald Silva | D14: =$J$6 -> 12000 | E14: =EDT!E19 -> 21 | F14: =D14*E14 -> 252000 | H14: Administrador BD | I14: =F5+F14+F23+F32+F41 -> 1860000
A15: QA | B15: Calidad Y Testing | C15: =IF(EDT!$J$9="","",EDT!$J$9) -> Kevin Herrera | D15: =$J$7 -> 8500 | E15: =EDT!F19 -> 14 | F15: =D15*E15 -> 119000 | H15: Calidad Y Testing | I15: =F6+F15+F24+F33+F42 -> 850000
A16: DI | B16: Diseñador | C16: =IF(EDT!$J$10="","",EDT!$J$10) -> Gerald Silva | D16: =$J$8 -> 8500 | E16: =EDT!G19 -> 18 | F16: =D16*E16 -> 153000 | H16: Diseñador | I16: =F7+F16+F25+F34+F43 -> 569500
B17: TOTAL FASE DISEÑO | E17: =SUM(E12:E16) -> 99 | F17: =SUM(F12:F16) -> 1136000 | H17: TOTAL COSTO | I17: =SUM(I12:I16) -> 6919500
A20: SIGLA | B20: ROL | C20: NOMBRE | D20: VALOR HORA HH | E20: HORAS | F20: FASE DESARROLLO | H20: COSTO POR FASE
A21: JP | B21: Jefe de Proyecto | C21: =IF(EDT!$J$6="","",EDT!$J$6) -> Christian Soto | D21: =$J$4 -> 16000 | E21: =EDT!C53 -> 31 | F21: =D21*E21 -> 496000 | H21: Fase de Planificación | I21: =F8 -> 522000
A22: AP | B22: Analista Programador | C22: =IF(EDT!$J$7="","",EDT!$J$7) -> Kevin Herrera | D22: =$J$5 -> 12000 | E22: =EDT!D53 -> 129 | F22: =D22*E22 -> 1548000 | H22: Fase de Análisis y Diseño | I22: =F17 -> 1136000
A23: DBA | B23: Desarrollador BD | C23: =IF(EDT!$J$8="","",EDT!$J$8) -> Gerald Silva | D23: =$J$6 -> 12000 | E23: =EDT!E53 -> 104 | F23: =D23*E23 -> 1248000 | H23: Fase de Desarrollo | I23: =F26 -> 3819000
A24: QA | B24: Calidad Y Testing | C24: =IF(EDT!$J$9="","",EDT!$J$9) -> Kevin Herrera | D24: =$J$7 -> 8500 | E24: =EDT!F53 -> 33 | F24: =D24*E24 -> 280500 | H24: Fase de QA | I24: =F35 -> 938500
A25: DI | B25: Diseñador | C25: =IF(EDT!$J$10="","",EDT!$J$10) -> Gerald Silva | D25: =$J$8 -> 8500 | E25: =EDT!G53 -> 29 | F25: =D25*E25 -> 246500 | H25: Fase de Implementación y Cierre | I25: =F44 -> 504000
B26: TOTAL FASE DESARROLLO | E26: =SUM(E21:E25) -> 326 | F26: =SUM(F21:F25) -> 3819000 | H26: TOTAL COSTO FASES | I26: =SUM(I21:I25) -> 6919500
A29: SIGLA | B29: ROL | C29: NOMBRE | D29: VALOR HORA HH | E29: HORAS | F29: FASE PRUEBAS QA | H29: Margen | I29: 0.6
A30: JP | B30: Jefe de Proyecto | C30: =IF(EDT!$J$6="","",EDT!$J$6) -> Christian Soto | D30: =$J$4 -> 16000 | E30: =EDT!C61 -> 7 | F30: =D30*E30 -> 112000 | H30: UTILIDAD | I30: =I26*I29 -> 4151700
A31: AP | B31: Analista Programador | C31: =IF(EDT!$J$7="","",EDT!$J$7) -> Kevin Herrera | D31: =$J$5 -> 12000 | E31: =EDT!D61 -> 22 | F31: =D31*E31 -> 264000 | H31: PRECIO FINAL | I31: =I26+I30 -> 11071200
A32: DBA | B32: Desarrollador BD | C32: =IF(EDT!$J$8="","",EDT!$J$8) -> Gerald Silva | D32: =$J$6 -> 12000 | E32: =EDT!E61 -> 15 | F32: =D32*E32 -> 180000
A33: QA | B33: Calidad Y Testing | C33: =IF(EDT!$J$9="","",EDT!$J$9) -> Kevin Herrera | D33: =$J$7 -> 8500 | E33: =EDT!F61 -> 41 | F33: =D33*E33 -> 348500 | H33: TOTAL HH PROYECTO | I33: =SUM(EDT!C70:G70) -> 600
A34: DI | B34: Diseñador | C34: =IF(EDT!$J$10="","",EDT!$J$10) -> Gerald Silva | D34: =$J$8 -> 8500 | E34: =EDT!G61 -> 4 | F34: =D34*E34 -> 34000
B35: TOTAL FASE PRUEBAS QA | E35: =SUM(E30:E34) -> 89 | F35: =SUM(F30:F34) -> 938500 | H35: Las columnas NOMBRE y HORAS se calculan solas:
H36: NOMBRE viene del Diccionario EDT y HORAS del subtotal de cada fase.
H37: Editar a mano solo J4:J8 (valor hora) e I29 (margen).
A38: SIGLA | B38: ROL | C38: NOMBRE | D38: VALOR HORA HH | E38: HORAS | F38: FASE IMPLEMENTACION Y CIERRE
A39: JP | B39: Jefe de Proyecto | C39: =IF(EDT!$J$6="","",EDT!$J$6) -> Christian Soto | D39: =$J$4 -> 16000 | E39: =EDT!C68 -> 8 | F39: =D39*E39 -> 128000
A40: AP | B40: Analista Programador | C40: =IF(EDT!$J$7="","",EDT!$J$7) -> Kevin Herrera | D40: =$J$5 -> 12000 | E40: =EDT!D68 -> 11 | F40: =D40*E40 -> 132000
A41: DBA | B41: Desarrollador BD | C41: =IF(EDT!$J$8="","",EDT!$J$8) -> Gerald Silva | D41: =$J$6 -> 12000 | E41: =EDT!E68 -> 9 | F41: =D41*E41 -> 108000
A42: QA | B42: Calidad Y Testing | C42: =IF(EDT!$J$9="","",EDT!$J$9) -> Kevin Herrera | D42: =$J$7 -> 8500 | E42: =EDT!F68 -> 6 | F42: =D42*E42 -> 51000
A43: DI | B43: Diseñador | C43: =IF(EDT!$J$10="","",EDT!$J$10) -> Gerald Silva | D43: =$J$8 -> 8500 | E43: =EDT!G68 -> 10 | F43: =D43*E43 -> 85000
B44: TOTAL FASE IMPLEMENTACION | E44: =SUM(E39:E43) -> 44 | F44: =SUM(F39:F43) -> 504000
